{
 "cells": [
  {
   "cell_type": "code",
   "execution_count": 1,
   "id": "bc78ec53",
   "metadata": {},
   "outputs": [
    {
     "name": "stderr",
     "output_type": "stream",
     "text": [
      "2023-06-23 01:35:27.687677: I tensorflow/core/platform/cpu_feature_guard.cc:182] This TensorFlow binary is optimized to use available CPU instructions in performance-critical operations.\n",
      "To enable the following instructions: AVX2 FMA, in other operations, rebuild TensorFlow with the appropriate compiler flags.\n"
     ]
    }
   ],
   "source": [
    "import pandas as pd\n",
    "import tensorflow as tf\n",
    "from tensorflow import keras\n",
    "from transformers import BertTokenizer, TFBertForSequenceClassification\n"
   ]
  },
  {
   "cell_type": "code",
   "execution_count": 2,
   "id": "51e5da04",
   "metadata": {},
   "outputs": [],
   "source": [
    "df = pd.read_csv(\"amazon_reviews_3.csv\")"
   ]
  },
  {
   "cell_type": "code",
   "execution_count": 7,
   "id": "d9487c1b",
   "metadata": {},
   "outputs": [],
   "source": [
    "train_texts = df['REVIEW_TEXT'].values\n",
    "train_labels = df['LABEL_ENCODED'].values"
   ]
  },
  {
   "cell_type": "code",
   "execution_count": 5,
   "id": "78990c0a",
   "metadata": {},
   "outputs": [],
   "source": [
    "train_labels = keras.utils.to_categorical(train_labels)"
   ]
  },
  {
   "cell_type": "code",
   "execution_count": 8,
   "id": "f441c383",
   "metadata": {},
   "outputs": [],
   "source": [
    "tokenizer = BertTokenizer.from_pretrained('bert-base-uncased')\n",
    "train_encodings = tokenizer.batch_encode_plus(\n",
    "    train_texts,\n",
    "    truncation=True,\n",
    "    padding=True,\n",
    "    max_length=128  # Adjust as needed\n",
    ")"
   ]
  },
  {
   "cell_type": "code",
   "execution_count": 13,
   "id": "e35f0eed",
   "metadata": {},
   "outputs": [],
   "source": [
    "dataset = tf.data.Dataset.from_tensor_slices((\n",
    "    dict(train_encodings),\n",
    "    train_labels\n",
    ")).shuffle(100)"
   ]
  },
  {
   "cell_type": "code",
   "execution_count": 14,
   "id": "31ea567a",
   "metadata": {},
   "outputs": [],
   "source": [
    "train_size = int(0.8 * len(dataset))\n",
    "train_dataset = dataset.take(train_size)\n",
    "val_dataset = dataset.skip(train_size)"
   ]
  },
  {
   "cell_type": "code",
   "execution_count": 15,
   "id": "d7aa0c58",
   "metadata": {},
   "outputs": [],
   "source": [
    "train_dataset = train_dataset.batch(32)  # Adjust batch size as needed\n",
    "val_dataset = val_dataset.batch(32)"
   ]
  },
  {
   "cell_type": "code",
   "execution_count": 16,
   "id": "6b49dd54",
   "metadata": {},
   "outputs": [
    {
     "name": "stderr",
     "output_type": "stream",
     "text": [
      "All PyTorch model weights were used when initializing TFBertForSequenceClassification.\n",
      "\n",
      "Some weights or buffers of the TF 2.0 model TFBertForSequenceClassification were not initialized from the PyTorch model and are newly initialized: ['classifier.weight', 'classifier.bias']\n",
      "You should probably TRAIN this model on a down-stream task to be able to use it for predictions and inference.\n"
     ]
    }
   ],
   "source": [
    "# Load the pre-trained BERT model with a classification head\n",
    "model = TFBertForSequenceClassification.from_pretrained('bert-base-uncased', num_labels=2)\n",
    "\n",
    "# Compile the model\n",
    "model.compile(\n",
    "    optimizer=tf.keras.optimizers.Adam(learning_rate=2e-5),\n",
    "    loss=tf.keras.losses.CategoricalCrossentropy(from_logits=True),\n",
    "    metrics=['accuracy']\n",
    ")"
   ]
  },
  {
   "cell_type": "code",
   "execution_count": 18,
   "id": "845922ba",
   "metadata": {},
   "outputs": [
    {
     "name": "stdout",
     "output_type": "stream",
     "text": [
      "Epoch 1/5\n"
     ]
    },
    {
     "name": "stderr",
     "output_type": "stream",
     "text": [
      "2023-06-23 01:45:03.929209: I tensorflow/core/common_runtime/executor.cc:1197] [/device:CPU:0] (DEBUG INFO) Executor start aborting (this does not indicate an error and you can ignore this message): INVALID_ARGUMENT: You must feed a value for placeholder tensor 'Placeholder/_3' with dtype int64 and shape [21000]\n",
      "\t [[{{node Placeholder/_3}}]]\n",
      "2023-06-23 01:45:03.929940: I tensorflow/core/common_runtime/executor.cc:1197] [/device:CPU:0] (DEBUG INFO) Executor start aborting (this does not indicate an error and you can ignore this message): INVALID_ARGUMENT: You must feed a value for placeholder tensor 'Placeholder/_3' with dtype int64 and shape [21000]\n",
      "\t [[{{node Placeholder/_3}}]]\n"
     ]
    },
    {
     "ename": "ValueError",
     "evalue": "in user code:\n\n    File \"/Users/kpandey/anaconda3/lib/python3.10/site-packages/keras/engine/training.py\", line 1284, in train_function  *\n        return step_function(self, iterator)\n    File \"/Users/kpandey/anaconda3/lib/python3.10/site-packages/keras/engine/training.py\", line 1268, in step_function  **\n        outputs = model.distribute_strategy.run(run_step, args=(data,))\n    File \"/Users/kpandey/anaconda3/lib/python3.10/site-packages/keras/engine/training.py\", line 1249, in run_step  **\n        outputs = model.train_step(data)\n    File \"/Users/kpandey/anaconda3/lib/python3.10/site-packages/transformers/modeling_tf_utils.py\", line 1692, in train_step\n        loss = self.compiled_loss(y, y_pred, sample_weight, regularization_losses=self.losses)\n    File \"/Users/kpandey/anaconda3/lib/python3.10/site-packages/keras/engine/compile_utils.py\", line 265, in __call__\n        loss_value = loss_obj(y_t, y_p, sample_weight=sw)\n    File \"/Users/kpandey/anaconda3/lib/python3.10/site-packages/keras/losses.py\", line 142, in __call__\n        losses = call_fn(y_true, y_pred)\n    File \"/Users/kpandey/anaconda3/lib/python3.10/site-packages/keras/losses.py\", line 268, in call  **\n        return ag_fn(y_true, y_pred, **self._fn_kwargs)\n    File \"/Users/kpandey/anaconda3/lib/python3.10/site-packages/keras/losses.py\", line 1984, in categorical_crossentropy\n        return backend.categorical_crossentropy(\n    File \"/Users/kpandey/anaconda3/lib/python3.10/site-packages/keras/backend.py\", line 5559, in categorical_crossentropy\n        target.shape.assert_is_compatible_with(output.shape)\n\n    ValueError: Shapes (None, 1) and (None, 2) are incompatible\n",
     "output_type": "error",
     "traceback": [
      "\u001b[0;31m---------------------------------------------------------------------------\u001b[0m",
      "\u001b[0;31mValueError\u001b[0m                                Traceback (most recent call last)",
      "Cell \u001b[0;32mIn[18], line 2\u001b[0m\n\u001b[1;32m      1\u001b[0m \u001b[38;5;66;03m# Train the model\u001b[39;00m\n\u001b[0;32m----> 2\u001b[0m \u001b[43mmodel\u001b[49m\u001b[38;5;241;43m.\u001b[39;49m\u001b[43mfit\u001b[49m\u001b[43m(\u001b[49m\n\u001b[1;32m      3\u001b[0m \u001b[43m    \u001b[49m\u001b[43mtrain_dataset\u001b[49m\u001b[43m,\u001b[49m\n\u001b[1;32m      4\u001b[0m \u001b[43m    \u001b[49m\u001b[43mepochs\u001b[49m\u001b[38;5;241;43m=\u001b[39;49m\u001b[38;5;241;43m5\u001b[39;49m\u001b[43m,\u001b[49m\u001b[43m  \u001b[49m\u001b[38;5;66;43;03m# Adjust the number of epochs as needed\u001b[39;49;00m\n\u001b[1;32m      5\u001b[0m \u001b[43m    \u001b[49m\u001b[43mvalidation_data\u001b[49m\u001b[43m \u001b[49m\u001b[38;5;241;43m=\u001b[39;49m\u001b[43m \u001b[49m\u001b[43mval_dataset\u001b[49m\n\u001b[1;32m      6\u001b[0m \u001b[43m)\u001b[49m\n",
      "File \u001b[0;32m~/anaconda3/lib/python3.10/site-packages/keras/utils/traceback_utils.py:70\u001b[0m, in \u001b[0;36mfilter_traceback.<locals>.error_handler\u001b[0;34m(*args, **kwargs)\u001b[0m\n\u001b[1;32m     67\u001b[0m     filtered_tb \u001b[38;5;241m=\u001b[39m _process_traceback_frames(e\u001b[38;5;241m.\u001b[39m__traceback__)\n\u001b[1;32m     68\u001b[0m     \u001b[38;5;66;03m# To get the full stack trace, call:\u001b[39;00m\n\u001b[1;32m     69\u001b[0m     \u001b[38;5;66;03m# `tf.debugging.disable_traceback_filtering()`\u001b[39;00m\n\u001b[0;32m---> 70\u001b[0m     \u001b[38;5;28;01mraise\u001b[39;00m e\u001b[38;5;241m.\u001b[39mwith_traceback(filtered_tb) \u001b[38;5;28;01mfrom\u001b[39;00m \u001b[38;5;28;01mNone\u001b[39;00m\n\u001b[1;32m     71\u001b[0m \u001b[38;5;28;01mfinally\u001b[39;00m:\n\u001b[1;32m     72\u001b[0m     \u001b[38;5;28;01mdel\u001b[39;00m filtered_tb\n",
      "File \u001b[0;32m/var/folders/tl/ps_r0r591fx137cf06vhn3tm0000gn/T/__autograph_generated_file1zbcektc.py:15\u001b[0m, in \u001b[0;36mouter_factory.<locals>.inner_factory.<locals>.tf__train_function\u001b[0;34m(iterator)\u001b[0m\n\u001b[1;32m     13\u001b[0m \u001b[38;5;28;01mtry\u001b[39;00m:\n\u001b[1;32m     14\u001b[0m     do_return \u001b[38;5;241m=\u001b[39m \u001b[38;5;28;01mTrue\u001b[39;00m\n\u001b[0;32m---> 15\u001b[0m     retval_ \u001b[38;5;241m=\u001b[39m ag__\u001b[38;5;241m.\u001b[39mconverted_call(ag__\u001b[38;5;241m.\u001b[39mld(step_function), (ag__\u001b[38;5;241m.\u001b[39mld(\u001b[38;5;28mself\u001b[39m), ag__\u001b[38;5;241m.\u001b[39mld(iterator)), \u001b[38;5;28;01mNone\u001b[39;00m, fscope)\n\u001b[1;32m     16\u001b[0m \u001b[38;5;28;01mexcept\u001b[39;00m:\n\u001b[1;32m     17\u001b[0m     do_return \u001b[38;5;241m=\u001b[39m \u001b[38;5;28;01mFalse\u001b[39;00m\n",
      "File \u001b[0;32m~/anaconda3/lib/python3.10/site-packages/transformers/modeling_tf_utils.py:1692\u001b[0m, in \u001b[0;36mTFPreTrainedModel.train_step\u001b[0;34m(self, data)\u001b[0m\n\u001b[1;32m   1689\u001b[0m             y_pred \u001b[38;5;241m=\u001b[39m y_pred[\u001b[38;5;241m0\u001b[39m]\n\u001b[1;32m   1691\u001b[0m     \u001b[38;5;28;01mif\u001b[39;00m loss \u001b[38;5;129;01mis\u001b[39;00m \u001b[38;5;28;01mNone\u001b[39;00m:\n\u001b[0;32m-> 1692\u001b[0m         loss \u001b[38;5;241m=\u001b[39m \u001b[38;5;28;43mself\u001b[39;49m\u001b[38;5;241;43m.\u001b[39;49m\u001b[43mcompiled_loss\u001b[49m\u001b[43m(\u001b[49m\u001b[43my\u001b[49m\u001b[43m,\u001b[49m\u001b[43m \u001b[49m\u001b[43my_pred\u001b[49m\u001b[43m,\u001b[49m\u001b[43m \u001b[49m\u001b[43msample_weight\u001b[49m\u001b[43m,\u001b[49m\u001b[43m \u001b[49m\u001b[43mregularization_losses\u001b[49m\u001b[38;5;241;43m=\u001b[39;49m\u001b[38;5;28;43mself\u001b[39;49m\u001b[38;5;241;43m.\u001b[39;49m\u001b[43mlosses\u001b[49m\u001b[43m)\u001b[49m\n\u001b[1;32m   1694\u001b[0m \u001b[38;5;66;03m# Run backwards pass.\u001b[39;00m\n\u001b[1;32m   1695\u001b[0m \u001b[38;5;28mself\u001b[39m\u001b[38;5;241m.\u001b[39moptimizer\u001b[38;5;241m.\u001b[39mminimize(loss, \u001b[38;5;28mself\u001b[39m\u001b[38;5;241m.\u001b[39mtrainable_variables, tape\u001b[38;5;241m=\u001b[39mtape)\n",
      "\u001b[0;31mValueError\u001b[0m: in user code:\n\n    File \"/Users/kpandey/anaconda3/lib/python3.10/site-packages/keras/engine/training.py\", line 1284, in train_function  *\n        return step_function(self, iterator)\n    File \"/Users/kpandey/anaconda3/lib/python3.10/site-packages/keras/engine/training.py\", line 1268, in step_function  **\n        outputs = model.distribute_strategy.run(run_step, args=(data,))\n    File \"/Users/kpandey/anaconda3/lib/python3.10/site-packages/keras/engine/training.py\", line 1249, in run_step  **\n        outputs = model.train_step(data)\n    File \"/Users/kpandey/anaconda3/lib/python3.10/site-packages/transformers/modeling_tf_utils.py\", line 1692, in train_step\n        loss = self.compiled_loss(y, y_pred, sample_weight, regularization_losses=self.losses)\n    File \"/Users/kpandey/anaconda3/lib/python3.10/site-packages/keras/engine/compile_utils.py\", line 265, in __call__\n        loss_value = loss_obj(y_t, y_p, sample_weight=sw)\n    File \"/Users/kpandey/anaconda3/lib/python3.10/site-packages/keras/losses.py\", line 142, in __call__\n        losses = call_fn(y_true, y_pred)\n    File \"/Users/kpandey/anaconda3/lib/python3.10/site-packages/keras/losses.py\", line 268, in call  **\n        return ag_fn(y_true, y_pred, **self._fn_kwargs)\n    File \"/Users/kpandey/anaconda3/lib/python3.10/site-packages/keras/losses.py\", line 1984, in categorical_crossentropy\n        return backend.categorical_crossentropy(\n    File \"/Users/kpandey/anaconda3/lib/python3.10/site-packages/keras/backend.py\", line 5559, in categorical_crossentropy\n        target.shape.assert_is_compatible_with(output.shape)\n\n    ValueError: Shapes (None, 1) and (None, 2) are incompatible\n"
     ]
    }
   ],
   "source": [
    "# Train the model\n",
    "model.fit(\n",
    "    train_dataset,\n",
    "    epochs=5,  # Adjust the number of epochs as needed\n",
    "    validation_data = val_dataset\n",
    ")"
   ]
  },
  {
   "cell_type": "code",
   "execution_count": null,
   "id": "35b9c1d0",
   "metadata": {},
   "outputs": [],
   "source": [
    "# Assuming you have test_texts containing new review texts\n",
    "test_encodings = tokenizer.batch_encode_plus(\n",
    "    test_texts,\n",
    "    truncation=True,\n",
    "    padding=True,\n",
    "    max_length=128  # Adjust as needed\n",
    ")\n",
    "\n",
    "test_dataset = tf.data.Dataset.from_tensor_slices(\n",
    "    dict(test_encodings)\n",
    ").batch(32)  # Adjust batch size as needed\n",
    "\n",
    "predictions = model.predict(test_dataset)"
   ]
  }
 ],
 "metadata": {
  "kernelspec": {
   "display_name": "Python 3 (ipykernel)",
   "language": "python",
   "name": "python3"
  },
  "language_info": {
   "codemirror_mode": {
    "name": "ipython",
    "version": 3
   },
   "file_extension": ".py",
   "mimetype": "text/x-python",
   "name": "python",
   "nbconvert_exporter": "python",
   "pygments_lexer": "ipython3",
   "version": "3.10.11"
  }
 },
 "nbformat": 4,
 "nbformat_minor": 5
}
